Workbook

Sheet Change_Log_v3
A1: ProstaCare Schema — V3 proposed changes
A2: Derived from the prostate-cancer MDT care pathway (NCCN/EAU, India). Every change is marked PROPOSED and awaits clinical sign-off (see DEV_START_GATE B11/B12).
A4: # | B4: Area | C4: Change | D4: Why (pathway capture point)
A5: 1 | B5: Demographics_Entry | C5: + religion, marital_status, education_level, occupation | D5: Patient demographics & risk factors (was captured in the demo, dropped in v2)
A6: 2 | B6: Demographics_Entry | C6: + tobacco_use | D6: Risk factors
A7: 3 | B7: Lab_Results (NEW sheet) | C7: Serial labs: PSA, Testosterone, CBC, RFT, LFT, ALP | D7: Key investigations; 6-weekly monitoring on Pluvicto
A8: 4 | B8: Treatment_Entry | C8: + Surgery section (surgery_type, surgery_date) | D8: Treatment options by stage: surgery
A9: 5 | B9: Treatment_Entry | C9: + Radioligand section (Lu-177 PSMA / Radium-223, cycles, dose, last cycle) | D9: Pluvicto therapy details (cycles, dose, AEs)
A10: 6 | B10: Adverse_Events (NEW sheet) | C10: Structured CTCAE-graded AEs | D10: Adverse events & toxicity
A11: 7 | B11: Outcomes_Entry | C11: + vital_status, date_of_death, cause_of_death | D11: Outcomes: OS (cannot be computed without these)
A12: 8 | B12: Outcomes_Entry | C12: + progression_free_date | D12: Outcomes: PFS
A13: 9 | B13: Bone_Events (NEW sheet) | C13: Skeletal-related events | D13: Outcomes: bone events
A14: 10 | B14: QoL_Assessments (NEW sheet) | C14: EQ-5D-5L / FACT-P | D14: Outcomes: QoL
A15: 11 | B15: Healthcare_Contacts (NEW sheet) | C15: Hospitalisation / ER visit / day-care | D15: Resource utilization
... A20: 16 | B20: Naming | C20: arsi_intensification — pathway calls it ARPI (decision pending) | D20: Terminology alignment
A22: Round 2 — visits & repeat treatment plans
A23: 17 | B23: Visits (NEW sheet) | C23: Every attendance recorded: date, type, disease state, outcome, next visit due | D23: Patient returns repeatedly; drives follow-up tracking
A24: 18 | B24: Treatment_Plans (NEW sheet) | C24: Treatment plan becomes ONE-TO-MANY (a dated version per line of therapy) | D24: A new plan is agreed at progression / toxicity
A25: 19 | B25: Treatment_Entry | C25: treatment_intent, mdt_status, date_of_mdt_review moved to Treatment_Plans | D25: They belong to a plan version, not to the patient
A26: 20 | B26: Dated sheets | C26: OPTIONAL visit_id link on PSA, labs, clinical, treatment, AEs, journey | D26: Groups everything captured at one visit; still valid without it
A27: 21 | B27: Follow-up | C27: next_visit_due_date + disease_state_at_visit drive the 'follow-up overdue' nudge | D27: Protocol intervals by disease state (pathway panel 5)

Sheet Platform_Bible
A1: ProstaCare Platform Bible
A2: A clinical operating system for oncology teams: registry, patient command centre, care-gap engine, cohort analytics, and governed intelligence in one experience.
A5: What It Is A bespoke oncology registry and workflow platform built for hospital teams. It captures structured case data, turns missing steps into visible nudges, and keeps cohort quality measurable. | E5: What It Feels Like Bright, calm, clinical, and high-trust. White surfaces, sky-blue emphasis, dark-blue anchors, rounded cards, quick drilldowns, and very little visual noise.
A10: What Users Do Start the day in triage, open any patient into a longitudinal file, complete workup and treatment state, route gaps to the MDT, and move from dashboard signal back to the exact patient. | E10: What It Captures A de-identified patient code, staging, pathology, imaging, biomarker history, treatment pathway, bone health, approvals, follow-up, outcomes, journey events, gaps, and collaboration touchpoints.
A15: Core Product Promise
A16: Every important cohort signal should be drillable back to a patient, and every important patient gap should be visible as an explainable next action.
A19: Major Surfaces
A20: Home | B20: A doctor-facing launchpad with quick actions, cohort pulse, benchmarks, surfaced cases, and nudge trends.
A21: Patient List | B21: A queue view organized by visit timing and urgency so teams can move from roster to chart quickly.
A22: Patient File | B22: A left-nav-driven longitudinal case file with demographics, clinical assessment, treatment plan, journey, and nudges.
A23: Population Dashboard | B23: A six-section analytics experience spanning overview, clinical profile, treatment, outcomes, quality, and demographics.
A24: AI Buddy | B24: A governed, step-by-step pathway review surface bounded to the configured evidence brain.
A26: Who This Bible Is For
A27: Product owners, clinical leads, designers, engineers, hospital stakeholders, and new developers who need to understand not only the data model, but also the intended experience, operating rhythm, and governed logic of the platform.

Sheet Visual_Language
A1: Visual Language
A2: This tab describes how the platform should look and feel when implemented: palette, type hierarchy, layout grammar, and interaction tone.
A4: Swatch | B4: Color Role | C4: Hex | D4: Usage | F4: Type Layer | G4: Font / Character | H4: Usage
B5: Primary Sky | C5: #2E92FF | D5: Main emphasis color for actions, highlights, selected navigation, and intelligence surfaces. | F5: Display | G5: Syne / DM Serif Display style | H5: Brand line, hero title, screen titles, bold clinical framing.
B6: Deep Blue | C6: #1D4F91 | D6: Anchor color for headers, hero surfaces, and high-trust framing. | F6: Body | G6: IBM Plex Sans / DM Sans style | H6: Forms, tables, descriptive copy, chart labels.
B7: Light Sky Wash | C7: #EAF4FF | D7: Card fills, scaffold bands, and elevated information blocks. | F7: Metric / System | G7: IBM Plex Mono / DM Mono style | H7: Unique patient codes, counters, metric chips, timestamps, status microcopy.
B8: Alert Red | C8: #D34B52 | D8: Critical gaps, progression warnings, and urgent attention states. | F8: Writing tone | G8: Direct, clinical, operational | H8: Explain signals and next steps clearly. Avoid vague product-marketing language inside the UI.
B9: Attention Amber | C9: #D58A1C | D9: Advisory gaps, pending review, and cautionary states.
B10: Support Green | C10: #4DB57A | D10: Healthy completion states and low-risk positive confirmation.
A13: Experience Rule | B13: What It Means In Practice | C13: Why It Matters
A14: Action-first | B14: Every major card should help the user do something next, not just read. | C14: The product is a working surface, not a brochure.
A15: Bright and breathable | B15: White background, pale sky-blue elevations, modest shadows, generous spacing. | C15: The platform should feel trustworthy and modern rather than heavy or gloomy.
A16: Clinical density without clutter | B16: Structured sections, clear labels, grouped controls, visible units and stages. | C16: Doctors should be able to read quickly without hunting.
A17: Color means urgency | B17: Blue = operating/default, amber = watch, red = urgent, green = complete. | C17: Signals must be scannable at a distance.
A18: Drilldown everywhere | B18: Metrics and charts should lead back to the patient list or patient file. | C18: The analytics layer must stay actionable.
A19: Governed intelligence | B19: AI Buddy stays stepwise, bounded, and evidence-anchored. | C19: The platform should feel intelligent without ever feeling improvisational.
A20: Explainable alerts | B20: A care gap should always show why it opened and what field or event would close it. | C20: Users need trust in the engine.

Sheet Screen_Blueprint
A1: Screen Blueprint
A2: Screen-by-screen explanation of what the user sees, what each surface is for, and what data or logic makes it useful.
A4: Surface | B4: Primary Job | C4: What The User Sees First | D4: Core Actions | E4: Visual Character | F4: Depends On
A5: Home | B5: Start-of-day command centre | C5: Warm welcome, department glance, quick actions, cohort pulse, benchmark cards, nudge trends, surfaced cases | D5: AI Buddy, Open Patient File, Go to Dashboard, Review Missed and High-Priority Patients, Review Care Gaps, Add New Patient | E5: Airy, bright, action-first, confidence-building | F5: User context, cohort metrics, care-gap engine, benchmark logic, surfaced-patient ranking
A6: Patient List | B6: Operational roster and search | C6: A searchable queue segmented by Last Visit, Upcoming, Missed / Overdue | D6: Search, filter by visit state, open any patient, add patient | E6: Fast, practical, low-noise, queue-oriented | F6: Patient master list, visit status, urgency signals
A7: Patient File Shell | B7: Single-patient command centre | C7: Unique patient code, status strip, quick metrics rail, left navigation, top utility actions | D7: Guidelines, Upload Rx, Discuss with Team, Print Summary, AI Buddy | E7: High-trust, clinically dense, still calm and legible | F7: Patient code, biomarker snapshot, treatment stage, role-based controls
A8: Patient File · Nudges & Alerts | B8: Make missing steps visible | C8: Severity-coded nudges with explainable reason and next-step expectation | D8: Acknowledge, route to team, mark acted/resolved | E8: Governed, sharp, operationally explicit | F8: Care-gap rules, case status, action trail
A9: Patient File · Demographics | B9: Capture de-identified registry and access context | C9: Unique code, age at diagnosis, coverage, geography, language, referral context | D9: Edit, save, keep the unique code synchronized | E9: Simple form blocks, low cognitive overhead | F9: Demographics_Entry
A10: Visit-wise entry
A11: Patient File · Clinical Assessment | B11: Capture disease workup and current state | C11: PSA history, biopsy, imaging, comorbidities, family history, staging | D11: Add PSA, update workup, complete staging | E11: Structured, evidence-ready, timeline-aware | F11: Clinical_Entry + PSA_History
A12: Patient File · Treatment Plan | B12: Capture intent and active management | C12: MDT status, systemic therapy, RT plan, bone health, supportive care | D12: Update treatment, log approvals, schedule follow-up | E12: Operational and therapy-centric | F12: Treatment_Entry
A13: Patient File · Patient Journey | B13: Show the whole case longitudinally | C13: Chronological event timeline from presentation to follow-up | D13: Add event, inspect treatment milestones | E13: Narrative but structured | F13: Journey_Events
A14: Team Discussion / Nudge Modal | B14: Close the loop across the MDT | C14: Recipient selector, reason, subject, note, discussion trail | D14: Notify team, document rationale, preserve auditability | E14: Collaborative, accountable, not chatty | F14: Nudge state + team directory + discussion log
A15: Guidelines Surface | B15: Keep guideline context close to the case | C15: Quick-reference rules, staging expectations, treatment checkpoints, India vs NCCN nuances | D15: Open guideline references during review | E15: Reference-first, not overwhelming | F15: Guideline pack configuration
A16: Population Dashboard | B16: Read the department or site as a living cohort | C16: Overview, Clinical Profile, Treatment, Outcomes, Quality & Gaps, Demographics | D16: Filter by time, drill into chart segments, export | E16: Analytical, panoramic, still clinically grounded | F16: Aggregated patient data + derived cohort fields
A17: AI Buddy | B17: Guided, stepwise pathway review | C17: A contained overlay with explicit steps, evidence status, and bounded next-path suggestions | D17: Continue step by step, open patient file, review access and trial routes | E17: Governed intelligence, not free-form generation | F17: Structured record + guideline packs + practice logs + retrospective signals + access rules

Sheet Workflow_Blueprint
A1: Workflow Blueprint
A2: The platform is best understood as a set of recurring clinical and operational workflows. This tab makes the rhythm explicit.
A4: Workflow | B4: Trigger | C4: Key Steps | D4: Output | E4: Visible Surfaces | F4: Success Signal
A5: Patient onboarding | B5: A new patient enters the registry | C5: Add New Patient -> complete demographics -> complete clinical workup shell -> initialize treatment and follow-up fields | D5: A searchable longitudinal record exists and appears in cohort counts | E5: Home, Patient File, Patient List | F5: Patient becomes visible in the operational system immediately.
A6: W1 Start-of-day clinical triage | B6: Doctor opens the platform at the start of clinic | C6: Scan Department at a glance -> review quick-action cards -> open surfaced patient or AI Buddy | D6: Highest-priority cases are pulled forward fast | E6: Home, Patient File, AI Buddy | F6: Minimal clicks from signal to chart to action.
A7: W2 Department patient review | B7: Doctor or staff scans the day’s list | C7: Filter patient list by visit status -> search -> open selected file -> check current nudges and treatment state | D7: Roster turns into an ordered working list | E7: Patient List, Patient File | F7: Queue state and patient urgency are obvious at a glance.
A8: Clinical workup completion | B8: The file is opened and staging / pathology is incomplete | C8: Enter PSA, biopsy, imaging, staging, comorbidity, family history -> save -> review resulting nudges | D8: The case becomes clinically interpretable and quality logic activates | E8: Patient File · Clinical Assessment, Care_Gap_Tracker | F8: Missing staging steps become explicit immediately.
A9: Treatment planning and update | B9: The team agrees a treatment pathway | C9: Record intent, MDT status, ADT / ARSI / RT details, approvals, supportive care, follow-up schedule | D9: Treatment state becomes auditable and cohort analytics update | E9: Patient File · Treatment Plan, Population Dashboard | F9: Therapy path and access barriers are documented, not implied.
A10: W4 Care-gap resolution | B10: A gap is generated by the engine | C10: Review why it opened -> acknowledge -> notify team if needed -> act -> mark resolved when documented | D10: The gap moves through a traceable lifecycle | E10: Patient File · Nudges, Team modal, Care_Gap_Tracker | F10: Signals are explainable and closure is logged.
A11: MDT governance | B11: A complex or high-risk case needs multidisciplinary sign-off | C11: Open file -> review workup and treatment plan -> discuss with team -> capture MDT outcome or waiver | D11: MDT completion becomes visible in both patient and cohort views | E11: Patient File, Team modal, Population Dashboard | F11: Governance is part of workflow, not a side process.
A12: W3 Cohort quality review | B12: Department lead or site admin opens the dashboard | C12: Move across overview, treatment, outcomes, quality, and demographics -> drill into any metric -> open underlying patients | D12: Population-level weakness turns into patient-level action | E12: Population Dashboard, Patient File | F12: Charts are not decorative; each one routes back to cases.
A13: AI Buddy guided review | B13: User wants a bounded, evidence-anchored pathway review | C13: Open AI Buddy -> move through the steps -> review guideline branch, retrospective pattern, access route, trials -> jump back to file | D13: A governed next-path view is surfaced without leaving context | E13: Home or Patient File, AI Buddy | F13: The system remains stepwise and auditable rather than chat-like.

Sheet Capture_Blueprint
A1: Capture Blueprint
A2: Grouped view of what the platform captures, where it is captured, what control style is used, and why the data matters clinically and analytically.
A4: Capture Domain | B4: What The Platform Captures | C4: Primary Sheet / Surface | D4: Control Style | E4: Why It Matters | F4: Used By
A5: Registry linkage | B5: Unique patient code, registry enrolment date, age at diagnosis | C5: Demographics_Entry | D5: Text, date, numeric | E5: Links every sheet and drives registration / age analytics without personal identifiers | F5: Patient header, list, dashboards
A6: Coverage and payer context | B6: Healthcare coverage, pre-auth state, referral centre, referral source | C6: Demographics_Entry + Treatment_Entry | D6: Dropdowns and dates | E6: Explains access delays, affordability, and approval bottlenecks | F6: Patient file, treatment analytics, quality charts
A7: Geography and access context | B7: State, travel distance, language preference | C7: Demographics_Entry | D7: Dropdowns and numeric | E7: Supports travel burden, language mix, and access planning without direct identifiers | F7: Demographics dashboard, patient context
A8: Referral context | B8: Referring centre and referral source | C8: Demographics_Entry | D8: Dropdowns | E8: Shows where patients come from and how the network behaves | F8: Home, demographics dashboard
A9: Presenting complaint | B9: Primary complaint, duration, IPSS, bowel/rectal symptoms | C9: Clinical_Entry | D9: Dropdowns, text | E9: Captures the initial clinical picture | F9: Patient file clinical view
A10: Physical and baseline exam | B10: DRE findings, prostate volume, ECOG, castration status | C10: Clinical_Entry | D10: Dropdowns, numeric | E10: Defines disease baseline and functional status | F10: Patient file, demographics and outcomes analytics
A11: Pathology | B11: Biopsy date/type, PI-RADS, Gleason, ISUP, cores, invasion markers | C11: Clinical_Entry | D11: Dropdowns, dates, numeric/text | E11: Defines grade and pathology risk | F11: Clinical analytics, pathway review
A12: Staging | B12: Clinical T/N/M stage and EAU risk category | C12: Clinical_Entry | D12: Dropdowns | E12: Anchors treatment pathway, quality logic, and cohort stratification | F12: Patient file, quality engine, dashboard
A13: Imaging and molecular workup | B13: mpMRI, bone scan/SPECT, PSMA PET-CT, CT A/P, DEXA, germline/somatic testing | C13: Clinical_Entry | D13: Dropdowns | E13: Feeds staging completeness, bone health logic, genomics eligibility | F13: Care gaps, clinical dashboard, AI Buddy
A14: Comorbidity and family history | B14: Active comorbidity flags and inherited risk context | C14: Clinical_Entry | D14: Yes/No flags | E14: Supports risk, supportive care, testing logic, and cohort comorbidity views | F14: Clinical dashboard, AI Buddy
A15: MDT and trial readiness | B15: MDT status/date and clinical-trial eligibility | C15: Treatment_Entry | D15: Dropdowns, dates | E15: Shows governance completion and future trial pathway readiness | F15: Treatment, quality, AI Buddy
... A23: Documents and collaboration | B23: Rx uploads, discussion notes, notifications, guideline references | C23: Workflow surfaces around the patient file | D23: File workflow + modal actions | E23: Keeps the record clinically usable and team-aware even where data is not purely tabular | F23: Patient file and governance flow

Sheet Governed_Intelligence
A1: Governed Intelligence
A2: Explains how the rules engine, cohort insighting, and AI Buddy should operate. This is the product’s intelligence boundary: what is allowed, what grounds it, and what must never become hallucinated.
A4: Capability | B4: What It Studies | C4: What It Returns | D4: Ground Truth / Brain | E4: What It Must Not Do | F4: Appears In
A5: Care-gap engine | B5: Structured case data is checked against configured staging, treatment, follow-up, and supportive-care rules | C5: Severity-coded nudges, gap counts, primary gap focus | D5: Versioned clinical rule packs approved by the clinical team | E5: It must not invent a gap outside configured rules | F5: Patient File, Care_Gap_Tracker, Home, Quality dashboard
A6: Protocol score | B6: Cohort adherence signals are rolled up across key rule families | C6: A cohort-level score and its biggest drag factors | D6: Rule-engine outputs plus benchmark configuration | E6: It must not present the score as unexplained magic | F6: Home, Population Dashboard
A7: Insight cards | B7: Cohort aggregates such as bone-health coverage, ARSI uptake, staging completeness | C7: Short statistical insights in plain language | D7: Registry aggregates and measured cohort counts | E7: It must not generate unsupported narrative claims | F7: Home, Reports
A8: AI Buddy · stepwise review | B8: Open case fields, current nudges, practice logs, retrospective outcome patterns, access rules | C8: A bounded, step-by-step pathway review with explicit next-path framing | D8: Governed evidence brain composed of structured records and approved evidence/config packs | E8: It must not behave like unconstrained chat or fabricate treatment branches | F8: Home, Patient File
A9: AI Buddy · progression branch | B9: Current line exposure, response history, CRPC/progression status, biomarkers, tolerance markers | C9: A structured view of plausible next pathway branches for review | D9: Guideline packs + retrospective pathway rules + patient state | E9: It must not claim autonomous clinical decision-making | F9: Patient File, AI Buddy
A10: AI Buddy · access and affordability lens | B10: Coverage, CGHS delays, local availability, configured access pathways | C10: Visible access route, delay risk, and documented fallback pathway | D10: Access-rule configuration and region-specific availability inputs | E10: It must not imply a drug is obtainable when the configured access layer says otherwise | F10: AI Buddy, Treatment planning
A11: AI Buddy · trial and new-drug lens | B11: Trial eligibility fields, geography, disease state, configured study sources | C11: Trial-screening prompts and governed study-fit suggestions | D11: Configured study source feeds and eligibility logic | E11: It must not hallucinate trial availability or sponsor access | F11: AI Buddy
A12: Brain boundary | B12: Only approved structured data and configured evidence sources are in scope | C12: High-confidence, explainable output | D12: Structured records, rule packs, guideline packs, practice logs, retrospective data, access pathways | E12: No free-text invention, no unsupported external facts, no hidden reasoning leaps | F12: Platform-wide governance principle

Sheet Instructions
A1: How To Use This Bible
A2: This workbook is now a platform bible first and a structured data-entry pack second. The opening tabs explain what the product is, how it should feel, how screens connect, what workflows it supports, and what it captures. The later tabs translate that product into data-entry structure, care-gap logic, and analytics coverage.
A4: Read order | B4: 1. Start with Platform_Bible and Visual_Language to understand the intended experience. 2. Read Screen_Blueprint, Workflow_Blueprint, and Capture_Blueprint to understand how the product behaves. 3. Read Home_Dashboard, Population_Dashboard, Dashboard_Derived, Dashboard_Coverage, and Governed_Intelligence to understand analytics and intelligence. 4. Use the entry tabs only when you need to inspect how the UI converts into structured capture.
A5: How to use the entry tabs | B5: Create one patient row in Demographics_Entry using the patient's unique patient code, then reuse the same code on Clinical_Entry, Treatment_Entry, Outcomes_Entry, PSA_History, and Journey_Events. Use dropdowns and Yes/No columns to mirror the UI controls. Review Dashboard and Care_Gap_Tracker for derived summaries.
A6: Sample rows included | B6: Rows 5-8 in the entry tabs are seeded with fully de-identified sample cases so the workbook can be reviewed immediately without adding manual data first.
A7: Sheets included | B7: Platform_Bible, Visual_Language, Screen_Blueprint, Workflow_Blueprint, Capture_Blueprint, Governed_Intelligence, Instructions, Field_Dictionary, Value_Lists, Dashboard, Home_Dashboard, Population_Dashboard, Dashboard_Derived, Dashboard_Coverage, Care_Gap_Tracker, Demographics_Entry, Clinical_Entry, Treatment_Entry, Outcomes_Entry, PSA_History, Journey_Events.
A8: Input color | B8: Light yellow cells are intended for manual entry.
A9: Derived color | B9: Light grey cells are calculated or should not be typed into directly.
A10: Required fields | B10: Headers marked with * should be treated as mandatory for workbook use. Field_Dictionary also shows whether a field is required in the UI versus required in the workbook.
A11: Multi-select chip groups | B11: In Excel, multi-select chip groups are represented as one Yes/No column per chip option.
A12: Date format | B12: Use yyyy-mm-dd across all date columns.
A13: Care gaps | B13: Care_Gap_Tracker applies the current nudge-style rules for staging, bone protection, DEXA, genetics, ARSI readiness, and follow-up. Psychosocial screening is treated as open when PHQ-9 is blank or Not done so the tracker stays actionable.
A14: Dashboard scope | B14: The product dashboard is larger than a simple KPI tab. The dedicated dashboard inventory tabs document home widgets, population analytics sections, derived cohort fields, drilldowns, and the remaining gaps that require application event history.
A15: Intelligence boundary | B15: Governed_Intelligence explains the approved intelligence surfaces. AI Buddy is described as a bounded evidence layer rather than unconstrained generation.
A16: File uploads | B16: Prescription / Rx upload is documented in Field_Dictionary but is not represented as a row-entry table because the UI uses a file attachment workflow.

Sheet Field_Dictionary
A1: Field Dictionary
A2: Each row maps one UI field (or one workbook representation of a UI field) to its entry mode, control type, options, and notes.
A4: Sheet | B4: UI Section | C4: Field Key | D4: Field Label | E4: UI Control | F4: Workbook Entry Mode | G4: Data Type | H4: UI Required | I4: Workbook Required | J4: Allowed Options / List | K4: Source ID / Notes | L4: Status
A5: Demographics_Entry | B5: Registry Linkage | C5: patient_code | D5: Unique Patient Code | E5: text | F5: Single column | G5: text | H5: No | I5: Yes | K5: Only patient-level identifier permitted in this workbook. Reuse the same code across all sheets. | L5: Existing (v2)
A6: Demographics_Entry | B6: Registry Linkage | C6: registry_enrolment_date | D6: Registry Enrolment Date | E6: date | F6: Single column | G6: date | H6: No | I6: No | J6: yyyy-mm-dd | K6: Needed for monthly registration trends on the home and population dashboards. | L6: Existing (v2)
A7: Demographics_Entry | B7: De-identified Demographics | C7: age_at_diagnosis_years | D7: Age at Diagnosis (years) | E7: number | F7: Single column | G7: whole number | H7: No | I7: Yes | J7: Years | K7: Enter numeric age at diagnosis. Do not capture date of birth. | L7: Existing (v2)
A8: Demographics_Entry | B8: De-identified Demographics | C8: language_preference | D8: Language Preference | E8: dropdown | F8: Single column | G8: categorical | H8: No | I8: No | J8: Hindi | English | Tamil | Telugu | Bengali | Marathi | Kannada | Malayalam | Gujarati | Punjabi | Odia | L8: Existing (v2)
A9: Demographics_Entry | B9: Coverage & Access | C9: healthcare_coverage | D9: Healthcare Coverage | E9: dropdown | F9: Single column | G9: categorical | H9: Yes | I9: Yes | J9: PMJAY (Ayushman Bharat) | CGHS | ESIC | State Scheme (Rajya Bima / Aarogyasri) | Private Insurance | Self-pay | L9: Existing (v2)
A10: Demographics_Entry | B10: Coverage & Access | C10: referring_hospital_centre | D10: Referring Hospital / Centre | E10: dropdown | F10: Single column | G10: categorical | H10: No | I10: No | J10: AIIMS New Delhi | Tata Memorial Centre, Mumbai | CMC Vellore | PGIMER Chandigarh | RGCI Delhi | SGPGI Lucknow | Government General Hospital | Private Urologist / Clinic | L10: Existing (v2)
A11: Demographics_Entry | B11: Coverage & Access | C11: referral_source | D11: Referral Source | E11: dropdown | F11: Single column | G11: categorical | H11: No | I11: No | J11: Government Hospital / OPD | Private Urologist | CGHS Panel Hospital | District Cancer Centre | Self-referral | Other | K11: Normalized for dashboard referral-source donut. | L11: Existing (v2)
A12: Demographics_Entry | B12: Geography & Access | C12: state | D12: State | E12: dropdown | F12: Single column | G12: categorical | H12: No | I12: No | J12: Delhi | Maharashtra | Tamil Nadu | Uttar Pradesh | Karnataka | West Bengal | Rajasthan | Punjab | Gujarat | Telangana | Andhra Pradesh | Madhya Pradesh | Bihar | Other | L12: Existing (v2)
A13: Demographics_Entry | B13: Geography & Access | C13: travel_distance_km | D13: Travel Distance to Centre (km) | E13: number | F13: Single column | G13: decimal number | H13: No | I13: No | J13: Kilometres | K13: Used for travel-distance chart buckets. | L13: Existing (v2)
A14: Clinical_Entry | B14: Workbook Linkage | C14: patient_code | D14: Unique Patient Code | E14: text | F14: Single column | G14: text | H14: No | I14: Yes | K14: Match the Demographics_Entry unique patient code. | L14: Existing (v2)
A15: Clinical_Entry | B15: Presenting Complaint | C15: diagnosis_date | D15: Date of Diagnosis | E15: date | F15: Single column | G15: date | H15: No | I15: No | J15: yyyy-mm-dd | K15: Needed for age-at-diagnosis and time-to-treatment analytics. | L15: Existing (v2)
A16: Clinical_Entry | B16: Presenting Complaint | C16: primary_complaint | D16: Primary Complaint | E16: dropdown | F16: Single column | G16: categorical | H16: No | I16: No | J16: LUTS (Lower urinary tract symptoms) | Haematuria | Bone pain / backache | Incidental PSA elevation | Asymptomatic screening | Urinary retention | L16: Existing (v2)
A17: Clinical_Entry | B17: Presenting Complaint | C17: duration | D17: Duration | E17: text | F17: Single column | G17: text | H17: No | I17: No | L17: Existing (v2)
A18: Clinical_Entry | B18: Presenting Complaint | C18: ipss_score | D18: IPSS Score | E18: dropdown | F18: Single column | G18: categorical | H18: No | I18: No | J18: 0–7 (Mild) | 8–19 (Moderate) | 20–35 (Severe) | L18: Existing (v2)
A19: Clinical_Entry | B19: Presenting Complaint | C19: bowel_rectal_symptoms | D19: Bowel / Rectal Symptoms | E19: dropdown | F19: Single column | G19: categorical | H19: No | I19: No | J19: None | Constipation | Blood in stool | Tenesmus | L19: Existing (v2)
A20: Clinical_Entry | B20: Digital Rectal Examination (DRE) | C20: dre_findings | D20: DRE Findings | E20: single-select chip group | F20: Dropdown | G20: categorical | H20: Yes | I20: No | J20: Normal | Enlarged (BPH) | Nodule – unilateral | Nodule – bilateral | Induration / fixity | Seminal vesicle ext. | L20: Existing (v2)
A21: Clinical_Entry | B21: Digital Rectal Examination (DRE) | C21: prostate_volume_cc | D21: Prostate Volume (TRUS / MRI cc) | E21: text | F21: Single column | G21: decimal number | H21: No | I21: No | J21: cc | K21: Workbook expects numeric cc value. | L21: Existing (v2)
A22: Clinical_Entry | B22: Biopsy Details | C22: biopsy_date | D22: Biopsy Date | E22: date | F22: Single column | G22: date | H22: No | I22: No | J22: yyyy-mm-dd | L22: Existing (v2)
A23: Clinical_Entry | B23: Biopsy Details | C23: biopsy_type | D23: Biopsy Type | E23: dropdown | F23: Single column | G23: categorical | H23: No | I23: No | J23: 12-core TRUS biopsy | MRI-targeted / Fusion biopsy | Cognitive targeted | Transperineal biopsy | TURP chips | L23: Existing (v2)
A24: Clinical_Entry | B24: Biopsy Details | C24: pi_rads_score | D24: PI-RADS Score (mpMRI) | E24: dropdown | F24: Single column | G24: categorical | H24: No | I24: No | J24: PI-RADS 1 | PI-RADS 2 | PI-RADS 3 | PI-RADS 4 | PI-RADS 5 | Not done | L24: Existing (v2)
A25: Clinical_Entry | B25: Biopsy Details | C25: gleason_score | D25: Gleason Score | E25: dropdown | F25: Single column | G25: categorical | H25: No | I25: No | J25: 3+3=6 | 3+4=7 | 4+3=7 | 4+4=8 | 4+5=9 | 5+4=9 | 5+5=10 | K25: gs | L25: Existing (v2)
A26: Clinical_Entry | B26: Biopsy Details | C26: isup_grade_group | D26: ISUP Grade Group | E26: dropdown | F26: Single column | G26: categorical | H26: No | I26: No | J26: Grade 1 (3+3) | Grade 2 (3+4) | Grade 3 (4+3) | Grade 4 (4+4) | Grade 5 (≥4+5) | L26: Existing (v2)
A27: Clinical_Entry | B27: Biopsy Details | C27: cores_positive_total | D27: Cores Positive / Total | E27: text | F27: Single column | G27: text | H27: No | I27: No | K27: UI stores as free text, e.g. 10 / 12. | L27: Existing (v2)
A28: Clinical_Entry | B28: Biopsy Details | C28: core_involvement_pct | D28: % Core Involvement | E28: text | F28: Single column | G28: decimal number | H28: No | I28: No | J28: % | K28: Workbook expects percent as whole number, e.g. 83. | L28: Existing (v2)
A29: Clinical_Entry | B29: Biopsy Details | C29: perineural_invasion | D29: Perineural Invasion | E29: dropdown | F29: Single column | G29: categorical | H29: No | I29: No | J29: Not assessed | Absent | Present | L29: Existing (v2)
A30: Clinical_Entry | B30: Biopsy Details | C30: ece_extracapsular_extension | D30: ECE (Extracapsular Extension) | E30: dropdown | F30: Single column | G30: categorical | H30: No | I30: No | J30: Not assessed | Absent | Present (radiological) | L30: Existing (v2)
A31: Clinical_Entry | B31: TNM Staging & Risk Classification | C31: clinical_t_stage | D31: Clinical T Stage | E31: dropdown | F31: Single column | G31: categorical | H31: Yes | I31: No | J31: cT1a | cT1b | cT1c | cT2a | cT2b | cT2c | cT3a | cT3b | cT4 | L31: Existing (v2)
A32: Clinical_Entry | B32: TNM Staging & Risk Classification | C32: n_stage | D32: N Stage | E32: dropdown | F32: Single column | G32: categorical | H32: No | I32: No | J32: cN0 | cN1 | cNX | L32: Existing (v2)
A33: Clinical_Entry | B33: TNM Staging & Risk Classification | C33: m_stage | D33: M Stage | E33: dropdown | F33: Single column | G33: categorical | H33: No | I33: No | J33: cM0 | M1a (Non-regional LN) | M1b (Bone mets) | M1c (Visceral mets) | L33: Existing (v2)
A34: Clinical_Entry | B34: TNM Staging & Risk Classification | C34: eau_risk_category | D34: EAU Risk Category | E34: dropdown | F34: Single column | G34: categorical | H34: No | I34: No | J34: Low | Intermediate – Favourable | Intermediate – Unfavourable | High | Very High / Locally Advanced | M1 – Metastatic HSPC | K34: risk-s | L34: Existing (v2)
A35: Clinical_Entry | B35: TNM Staging & Risk Classification | C35: ecog_performance_status | D35: ECOG Performance Status | E35: dropdown | F35: Single column | G35: categorical | H35: No | I35: No | J35: 0 – Fully active | 1 – Restricted strenuous activity | 2 – Ambulatory, self-care only | 3 – Limited self-care | 4 – Completely disabled | L35: Existing (v2)
A36: Clinical_Entry | B36: TNM Staging & Risk Classification | C36: castration_status | D36: Castration Status | E36: dropdown | F36: Single column | G36: categorical | H36: No | I36: No | J36: Hormone-sensitive (HSPC) | Castration-resistant (CRPC) | Not on ADT | K36: cast-s | L36: Existing (v2)
A37: Clinical_Entry | B37: Imaging & Molecular Workup | C37: mpmri_pelvis | D37: mpMRI Pelvis | E37: dropdown | F37: Single column | G37: categorical | H37: No | I37: No | J37: Not done | Done — abnormal | Done — normal | L37: Existing (v2)
A38: Clinical_Entry | B38: Imaging & Molecular Workup | C38: bone_scan_spect | D38: Bone Scan / SPECT | E38: dropdown | F38: Single column | G38: categorical | H38: No | I38: No | J38: Not done | Done — no metastases | Done — bone metastases present | K38: bone-s | L38: Existing (v2)
A39: Clinical_Entry | B39: Imaging & Molecular Workup | C39: psma_pet_ct | D39: PSMA PET-CT | E39: dropdown | F39: Single column | G39: categorical | H39: No | I39: No | J39: Not done | Done — no uptake | Done — pelvic nodal uptake | Done — distant metastases | K39: psma-s | L39: Existing (v2)
A40: Clinical_Entry | B40: Imaging & Molecular Workup | C40: ct_abdomen_pelvis | D40: CT Chest / Abdomen / Pelvis | E40: dropdown | F40: Single column | G40: categorical | H40: No | I40: No | J40: Not done | Done — lymphadenopathy | Done — normal | L40: AMENDED (v3) — label
A41: Clinical_Entry | B41: Imaging & Molecular Workup | C41: dexa_bone_density | D41: DEXA Bone Density | E41: dropdown | F41: Single column | G41: categorical | H41: No | I41: No | J41: Not done | Normal (T-score ≥ −1) | Osteopenia (T −1 to −2.5) | Osteoporosis (T-score < −2.5) | K41: dexa-s | L41: Existing (v2)
...

Sheet Value_Lists
A1: Value Lists
A2: Reference sheet for every dropdown or Yes/No option set used by the entry tabs. The entry tabs use inline validations, but this sheet keeps the lists visible for review.
A4: List Name | B4: Option Order | C4: Option Value | D4: Control Notes
A5: yesNo | B5: 1 | D5: Used for multi-select chip flags in workbook form.
A6: yesNo | B6: 2 | C6: Yes | D6: Used for multi-select chip flags in workbook form.
A7: yesNo | B7: 3 | C7: No | D7: Used for multi-select chip flags in workbook form.
A8: languagePreference | B8: 1 | C8: Hindi | D8: Used as dropdown values.
A9: languagePreference | B9: 2 | C9: English | D9: Used as dropdown values.
A10: languagePreference | B10: 3 | C10: Tamil | D10: Used as dropdown values.
A11: languagePreference | B11: 4 | C11: Telugu | D11: Used as dropdown values.
A12: languagePreference | B12: 5 | C12: Bengali | D12: Used as dropdown values.
A13: languagePreference | B13: 6 | C13: Marathi | D13: Used as dropdown values.
A14: languagePreference | B14: 7 | C14: Kannada | D14: Used as dropdown values.
A15: languagePreference | B15: 8 | C15: Malayalam | D15: Used as dropdown values.
A16: languagePreference | B16: 9 | C16: Gujarati | D16: Used as dropdown values.
A17: languagePreference | B17: 10 | C17: Punjabi | D17: Used as dropdown values.
... A411: reasonForPlanChange | B411: 7 | C411: Comorbidity | D411: PROPOSED (v3) — visits & treatment plans

Sheet Dashboard
A1: Dashboard Quick Summary
A2: Operational roll-up derived from the entry tabs and the Care_Gap_Tracker sheet. Use the dedicated Home_Dashboard and Population_Dashboard tabs for the full analytics inventory and logic map.
A4: Registered Patients | C4: Patients With Any Gap | E4: Total Open Gaps | G4: Patients With Urgent Gap | I4: High / Very High / M1 | K4: Follow-up PSA Pending
A5: =COUNTIF(Demographics_Entry!$A$5:$A$104,"<>") | C5: =COUNTIF(Care_Gap_Tracker!$X$5:$X$104,">0") | E5: =SUM(Care_Gap_Tracker!$X$5:$X$104) | G5: =COUNTIF(Care_Gap_Tracker!$U$5:$U$104,">0") | I5: =COUNTIF(Care_Gap_Tracker!$C$5:$C$104,"High")+COUNTIF(Care_Gap_Tracker!$C$5:$C$104,"Very High / Locally Advanced")+COUNTIF(Care_Gap_Tracker!$C$5:$C$104,"M1 – Metastatic HSPC") | K5: =SUM(Care_Gap_Tracker!$S$5:$S$104)
A9: Gap Type | B9: Severity | C9: Open Count | D9: Formula Basis | F9: Severity | G9: Patient Count | H9: Open Gap Count
A10: Bone Scan / SPECT missing | B10: Urgent | C10: =SUM(Care_Gap_Tracker!$M$5:$M$104) | D10: High / very high / M1 with Bone Scan = Not done | F10: Urgent | G10: =COUNTIF(Care_Gap_Tracker!$U$5:$U$104,">0") | H10: =SUM(Care_Gap_Tracker!$U$5:$U$104)
A11: PSMA PET-CT missing | B11: Urgent | C11: =SUM(Care_Gap_Tracker!$N$5:$N$104) | D11: High / very high with PSMA = Not done | F11: Warning | G11: =COUNTIF(Care_Gap_Tracker!$V$5:$V$104,">0") | H11: =SUM(Care_Gap_Tracker!$V$5:$V$104)
A12: Bone protection not started | B12: Urgent | C12: =SUM(Care_Gap_Tracker!$O$5:$O$104) | D12: Bone Protection Therapy = Not started | F12: Info | G12: =COUNTIF(Care_Gap_Tracker!$W$5:$W$104,">0") | H12: =SUM(Care_Gap_Tracker!$W$5:$W$104)
A13: DEXA not done | B13: Warning | C13: =SUM(Care_Gap_Tracker!$P$5:$P$104) | D13: DEXA Bone Density = Not done
A14: Genomics not done | B14: Warning | C14: =SUM(Care_Gap_Tracker!$Q$5:$Q$104) | D14: Germline / Somatic Testing = Not done
A15: ARSI readiness gap | B15: Warning | C15: =SUM(Care_Gap_Tracker!$R$5:$R$104) | D15: HSPC + High risk + ARSI = Not initiated | F15: Operational Metric | G15: Value | H15: Formula Basis
A16: Follow-up PSA not scheduled | B16: Info | C16: =SUM(Care_Gap_Tracker!$S$5:$S$104) | D16: Next Follow-up PSA Date blank | F16: Clinical rows entered | G16: =COUNTIF(Clinical_Entry!$A$5:$A$104,"<>") | H16: Clinical_Entry patients with unique code
A17: Psychosocial screening prompt | B17: Info | C17: =SUM(Care_Gap_Tracker!$T$5:$T$104) | D17: PHQ-9 blank or Not done | F17: Treatment rows entered | G17: =COUNTIF(Treatment_Entry!$A$5:$A$104,"<>") | H17: Treatment_Entry patients with unique code
F18: PSA entries logged | G18: =COUNTIF(PSA_History!$A$5:$A$154,"<>") | H18: PSA_History rows with unique code
F19: Journey events logged | G19: =COUNTIF(Journey_Events!$A$5:$A$154,"<>") | H19: Journey_Events rows with unique code
F20: Gap burden per patient | G20: =IF(COUNTIF(Demographics_Entry!$A$5:$A$104,"<>")=0,0,SUM(Care_Gap_Tracker!$X$5:$X$104)/COUNTIF(Demographics_Entry!$A$5:$A$104,"<>")) | H20: Total open gaps / registered patients
F21: Patients with any gap % | G21: =IF(COUNTIF(Demographics_Entry!$A$5:$A$104,"<>")=0,0,COUNTIF(Care_Gap_Tracker!$X$5:$X$104,">0")/COUNTIF(Demographics_Entry!$A$5:$A$104,"<>")) | H21: Patients with any gap / registered patients

Sheet Home_Dashboard
A1: Home Dashboard Inventory
A2: Inventory of the actual home screen widgets, actions, cards, and operational lists. This tab is documentation/specification: it explains what the home surface shows and what dataset or logic drives it.
A4: Zone | B4: Widget / Feature | C4: Surface Type | D4: What It Shows | E4: Primary Driver | F4: Action / Drilldown | G4: Implementation Notes
A5: Header | B5: Doctor welcome + cohort chips | C5: Context header | D5: Doctor identity, role, department, hospital, cohort count, active care-gap count | E5: Logged-in user context + cohort counts | F5: Links to overview and quality dashboard sections | G5: This is the operational launch point for start-of-day triage.
A6: At a glance | B6: Department at a glance | C6: 4-metric summary card | D6: Last visit, upcoming, missed/overdue, population alerts | E6: Visit-status counts + insight-card counts | F6: No separate drilldown; supports quick situational scan | G6: Maps to the PRD home / welcome screen.
A7: Action card | B7: AI Buddy | C7: Guided action card | D7: Step-by-step pathway review | E7: Structured record + rule packs + practice logs + retrospective signals + access rules | F7: Opens AI Buddy overlay | G7: Workflow feature, not a row-based data-entry table.
A8: Action card | B8: Open Patient File | C8: Action card | D8: Department roster and patient queue | E8: Patient list, visit status, search | F8: Opens patient list | G8: Operational entry point rather than cohort analytics.
A9: Action card | B9: Go to Dashboard | C9: Action card | D9: Population charts and insight cards | E9: Population analytics dataset | F9: Opens population dashboard | G9: Direct route to full analytics surface.
A10: Action card | B10: Review Missed and High-Priority Patients | C10: Action card | D10: Flagged critical and recommendation patients | E10: Care-gap severity + urgent roster logic | F10: Scrolls to surfaced attention section | G10: Home triage shortcut.
A11: Action card | B11: Review Care Gaps | C11: Action card | D11: Quality & gaps view | E11: Care-gap engine | F11: Opens quality section in population dashboard | G11: Uses the same underlying nudge logic as the patient file.
A12: Action card | B12: Add New Patient | C12: Action card | D12: New registry entry | E12: Patient onboarding workflow | F12: Opens patient file in new-patient mode | G12: Workflow control, not analytics.
A13: Cohort health | B13: Protocol adherence score | C13: KPI card + progress bar | D13: Overall cohort protocol score | E13: Composite rule adherence calculation | F13: Home drilldown modal | G13: The score driver text explicitly references bone protection and PSMA staging gaps.
A14: Cohort health | B14: Open care gaps | C14: KPI card + sparkline | D14: Total active care gaps | E14: Open nudge / gap count | F14: Home drilldown modal | G14: Trend compared month-on-month.
A15: Cohort health | B15: Record completeness | C15: KPI card + sparkline | D15: Fully entered records vs total | E15: Field-group completeness | F15: Home drilldown modal | G15: Requires completeness logic across patient sections.
... A26: Review | B26: Incomplete records — data entry pending | C26: Operational list | D26: Patients missing key fields | E26: Completeness rules by patient | F26: Open patient list | G26: Important for registrar / coordinator workflows.

Sheet Population_Dashboard
A1: Population Dashboard Inventory
A2: Full map of the actual analytics dashboard in population-analytics.html. Each row represents a KPI card, chart, funnel, or section-level analytic surface with its filter scope, drilldown behavior, and required data.
A4: Section | B4: Widget ID | C4: Widget / Chart | D4: Type | E4: Time Filters | F4: Primary Measure | G4: Buckets / Segments | H4: Drilldown / Interaction | I4: Current Workbook Source | J4: Extra Derivation / Notes
A5: Overview | B5: snapshot | C5: Sidebar snapshot | D5: Summary metrics | E5: 3M / 1Y / All time | F5: High/VH Risk, Active ADT, ARSI Intensified, Care Gaps Open, Median PSA, Protocol Score | G5: None | H5: Persistent sidebar state | I5: Clinical_Entry risk + Treatment_Entry + Care_Gap_Tracker + PSA_History | J5: Median/latest logic and protocol score are derived
A6: Overview | B6: overview-kpis | C6: Total Patients / High-VH Risk / Median PSA / Active ADT / Protocol Score | D6: KPI row | E6: 3M / 1Y / All time | F6: Cohort volume and top-line performance | G6: Five KPI cards | H6: No chart drilldown; section-level anchors | I6: Demographics_Entry, Clinical_Entry, Treatment_Entry, PSA_History | J6: Protocol score is composite
A7: Overview | B7: c-reg | C7: Monthly registrations + cumulative cohort | D7: Bar + line | E7: 3M / 1Y / All time | F7: Monthly new patients and cumulative cohort | G7: Month buckets | H7: Click month to patient list | I7: Demographics_Entry.registry_enrolment_date | J7: Needs period bucket derivation
A8: Overview | B8: c-risk | C8: Risk distribution | D8: Donut | E8: 3M / 1Y / All time | F8: Risk mix | G8: Low, intermediate, high, very high / locally advanced, metastatic | H8: Click segment to patient list | I8: Clinical_Entry.eau_risk_category | J8: Requires normalized risk grouping
A9: Overview | B9: c-age | C9: Age at diagnosis | D9: Histogram | E9: 3M / 1Y / All time | F9: Age distribution | G9: Age bands | H9: Click bar to patient list | I9: Demographics_Entry.age_at_diagnosis_years | J9: Age is captured directly as a de-identified field
A10: Overview | B10: c-cov | C10: Healthcare coverage | D10: Donut | E10: 3M / 1Y / All time | F10: Coverage mix | G10: CGHS, PMJAY, ESIC, Private, Self-pay | H10: Legend-only in demo | I10: Demographics_Entry.healthcare_coverage | J10: May need normalized grouping
A11: Overview | B11: c-stage | C11: Stage at presentation | D11: Bar | E11: 3M / 1Y / All time | F11: Stage distribution | G11: cT / N / M grouped presentation buckets | H11: Click bar to patient list | I11: Clinical_Entry.clinical_t_stage, n_stage, m_stage | J11: Needs stage bucket derivation
A12: Clinical | B12: c-psadx | C12: PSA at diagnosis — distribution | D12: Histogram | E12: 3M / 1Y / All time | F12: Diagnostic PSA distribution | G12: PSA bands | H12: Click band to patient list | I12: PSA_History.psa_ng_ml + diagnosis context | J12: Needs first/diagnostic PSA selection
A13: Clinical | B13: c-psatrend | C13: PSA trend — cohort median + percentile bands | D13: Line chart | E13: 3M / 1Y / All time | F13: Longitudinal PSA movement | G13: Time periods with percentile bands | H13: No patient-level drill in demo | I13: PSA_History dates + values | J13: Requires time-series aggregation
A14: Clinical | B14: c-gleason | C14: Gleason / ISUP grade | D14: Bar | E14: 3M / 1Y / All time | F14: Pathology risk distribution | G14: Gleason or grade-group buckets | H14: Click grade to patient list | I14: Clinical_Entry.gleason_score, isup_grade_group | J14: Grade mapping derived
A15: Clinical | B15: c-psaden | C15: PSA density distribution | D15: Bar | E15: 3M / 1Y / All time | F15: PSA density spread | G15: Density bands | H15: No explicit drilldown label in UI | I15: PSA_History.psa_density | J15: Band derivation required
... A46: Demographics | B46: c-ecog | C46: ECOG performance status | D46: Donut + progress bars | E46: 3M / 1Y / All time | F46: Functional status mix | G46: ECOG 0/1/2/3 | H46: Click donut segment to patient list | I46: Clinical_Entry.ecog_performance_status | J46: Already captured with normalization

Sheet Dashboard_Derived
A1: Dashboard Derived Fields & Logic
A2: Many dashboard widgets rely on derived cohort fields rather than direct form columns. This tab lists those derived items, where they are used, and whether the workbook now captures the required source fields.
A4: Derived Field | B4: Used By | C4: Derivation Logic | D4: Source Fields | E4: Coverage | F4: Notes
A5: period bucket | B5: Home registrations, c-reg, c-psatrend, c-mdt | C5: Bucket each date into 3M / 1Y / All-time periods and month labels | D5: Registry enrolment date, PSA dates, MDT review date | E5: Partial | F5: Requires aggregation logic rather than new patient fields.
A6: risk group normalization | B6: c-risk, benchmark cards, protocol score | C6: Collapse UI risk labels into cohort risk groups | D6: Clinical_Entry.eau_risk_category | E6: Yes | F6: Directly supported from current risk field.
A7: stage-at-presentation bucket | B7: c-stage, heatmap, outcomes stratification | C7: Map T/N/M fields into presentation buckets | D7: Clinical_Entry.clinical_t_stage, n_stage, m_stage | E7: Yes | F7: Derived grouping required.
A8: age at diagnosis | B8: c-age | C8: Use numeric age-at-diagnosis entry directly, then bucket into dashboard age bands | D8: Demographics_Entry.age_at_diagnosis_years | E8: Yes | F8: This keeps the workbook de-identified while preserving the age histogram.
A9: diagnostic PSA selection | B9: c-psadx, heatmap | C9: Select PSA reading associated with diagnosis window or marked diagnostic context | D9: PSA_History | E9: Partial | F9: Needs consistent PSA-history entry practice.
A10: PSA density band | B10: c-psaden | C10: Bucket PSA density into configured bands | D10: PSA_History.psa_density | E10: Yes | F10: Band edges remain analytics config.
A11: free PSA band | B11: c-freepsa | C11: Bucket free PSA % into configured bands | D11: PSA_History.free_psa_pct | E11: Yes | F11: Band edges remain analytics config.
A12: comorbidity mask | B12: c-comorbid, c-comorbpair | C12: Convert Yes/No flags into one-hot and pair combinations | D12: Clinical_Entry comorbidity columns | E12: Yes | F12: Workbook stores each comorbidity as a separate flag.
A13: ADT duration bucket | B13: c-adtdur | C13: DATEDIF(ADT Start Date, today/filter end) | D13: Treatment_Entry.adt_start_date | E13: Yes | F13: Time filter affects active duration.
A14: treatment started flag | B14: Treatment funnel, c-timetotx | C14: Treatment start present when first active treatment date exists | D14: Treatment_Entry.treatment_start_date | E14: Yes | F14: Added for clean time-to-treatment logic.
A15: RT completed flag | B15: Treatment KPI row, funnel, c-rtoutcome | C15: RT status = Completed or RT Completion Date present | D15: Treatment_Entry.rt_status, rt_completion_date | E15: Yes | F15: Added in this revision.
... A26: nudge lifecycle history | B26: Home nudge trends, c-nudgetrend | C26: Track Opened, Viewed, Acted Upon, Resolved events over time | D26: Historical nudge events | E26: No | F26: Still requires a dedicated event log beyond patient snapshot tables.

Sheet Dashboard_Coverage
A1: Dashboard Coverage Check
A2: Coverage check between the real product dashboard and this Excel-based registry workbook. Use this tab during handover to show what is already modeled, what is partially modeled, and what still depends on application event history or non-tabular workflow data.
A4: Analytics Requirement | B4: Coverage Status | C4: Current Workbook Support | D4: Recommended Handling | E4: Why It Matters
A5: Home and population registration trends | B5: Covered | C5: Demographics_Entry.registry_enrolment_date | D5: Use enrolment date as the month-series anchor | E5: Added in this revision.
A6: Age at diagnosis | B6: Covered | C6: Demographics_Entry.age_at_diagnosis_years | D6: Derive age bucket in analytics layer | E6: Needed for the overview histogram.
A7: Referral source donut | B7: Covered | C7: Demographics_Entry.referral_source | D7: Normalize to dashboard referral buckets | E7: Added in this revision.
A8: Travel distance chart | B8: Covered | C8: Demographics_Entry.travel_distance_km | D8: Bucket into dashboard distance ranges | E8: Added in this revision.
A9: CGHS delay and pending approvals | B9: Covered | C9: Treatment_Entry.cghs_preauth_status, cghs_request_date, cghs_approval_date | D9: Derive delay days and pending counts | E9: Added in this revision.
A10: RT completed / active analytics | B10: Covered | C10: Treatment_Entry.rt_status, rt_completion_date | D10: Use status plus completion date | E10: Added in this revision.
A11: Time-to-treatment analytics | B11: Covered | C11: Clinical_Entry.diagnosis_date + Treatment_Entry.treatment_start_date | D11: Derive day buckets | E11: Added in this revision.
A12: Outcome cards and progression analytics | B12: Covered | C12: Outcomes_Entry + PSA_History + Treatment_Entry | D12: Use outcome snapshot sheet for recurrence, nadir, CRPC progression, RT outcome | E12: Added in this revision.
A13: PSA distribution and trend charts | B13: Partial | C13: PSA_History | D13: Enter diagnostic and follow-up PSA rows consistently | E13: The workbook supports capture; the analytics layer still chooses which rows drive each chart.
A14: Protocol adherence radar | B14: Partial | C14: Clinical_Entry, Treatment_Entry, Care_Gap_Tracker | D14: Requires composite benchmark calculation | E14: Source fields exist; scoring logic sits outside Excel.
A15: Bone-health quality donut | B15: Covered | C15: Clinical_Entry + Treatment_Entry + Care_Gap_Tracker | D15: Derive bone-gap categories from therapy / DEXA / calcium-Vit D | E15: Current workbook already holds the source fields.
... A20: Home surfaced patient cards | B20: Partial | C20: Can be driven from Care_Gap_Tracker + case headers | D20: Needs prioritization logic and recent activity context | E20: The workbook has the clinical source data but not the UI ranking rules.

Sheet Care_Gap_Tracker
A1: Care Gap Tracker
A2: Derived sheet. Rules are based on the current patient-file nudge logic for staging, bone protection, DEXA, genetics, ARSI readiness, and follow-up. The tracker uses unique patient codes only. Psychosocial screening is opened when PHQ-9 is blank or Not done so the tracker remains usable in Excel.
A4: Unique Patient Code | B4: Healthcare Coverage | C4: Risk Category | D4: Castration Status | E4: Bone Scan / SPECT | F4: PSMA PET-CT | G4: Bone Protection Therapy | H4: DEXA Bone Density | I4: Germline / Somatic Testing | J4: ARSI Intensification | K4: Next Follow-up PSA Date | L4: Psychosocial Screening (PHQ-9) | M4: Urgent: Bone Scan Missing | N4: Urgent: PSMA Missing | O4: Urgent: Bone Protection Missing | P4: Warning: DEXA Missing | Q4: Warning: Genetics Missing | R4: Warning: ARSI Readiness Gap | S4: Info: Follow-up Missing | T4: Info: Psychosocial Prompt | U4: Urgent Gap Count | V4: Warning Gap Count | W4: Info Gap Count | X4: Total Open Gaps | Y4: Highest Severity | Z4: Primary Gap Focus | AA4: Care Gap Summary
A5: =IF(Demographics_Entry!$A5="","",Demographics_Entry!$A5) | B5: =IF($A5="","",IFERROR(INDEX(Demographics_Entry!$E$5:$E$104,MATCH($A5,Demographics_Entry!$A$5:$A$104,0)),"")) | C5: =IF($A5="","",IFERROR(INDEX(Clinical_Entry!$U$5:$U$104,MATCH($A5,Clinical_Entry!$A$5:$A$104,0)),"")) | D5: =IF($A5="","",IFERROR(INDEX(Clinical_Entry!$W$5:$W$104,MATCH($A5,Clinical_Entry!$A$5:$A$104,0)),"")) | E5: =IF($A5="","",IFERROR(INDEX(Clinical_Entry!$Y$5:$Y$104,MATCH($A5,Clinical_Entry!$A$5:$A$104,0)),"")) | F5: =IF($A5="","",IFERROR(INDEX(Clinical_Entry!$Z$5:$Z$104,MATCH($A5,Clinical_Entry!$A$5:$A$104,0)),"")) | G5: =IF($A5="","",IFERROR(INDEX(Treatment_Entry!$AA$5:$AA$104,MATCH($A5,Treatment_Entry!$A$5:$A$104,0)),"")) | H5: =IF($A5="","",IFERROR(INDEX(Clinical_Entry!$AB$5:$AB$104,MATCH($A5,Clinical_Entry!$A$5:$A$104,0)),"")) | I5: =IF($A5="","",IFERROR(INDEX(Clinical_Entry!$AC$5:$AC$104,MATCH($A5,Clinical_Entry!$A$5:$A$104,0)),"")) | J5: =IF($A5="","",IFERROR(INDEX(Treatment_Entry!$K$5:$K$104,MATCH($A5,Treatment_Entry!$A$5:$A$104,0)),"")) | K5: =IF($A5="","",IFERROR(INDEX(Treatment_Entry!$AC$5:$AC$104,MATCH($A5,Treatment_Entry!$A$5:$A$104,0)),"")) | L5: =IF($A5="","",IFERROR(INDEX(Treatment_Entry!$AE$5:$AE$104,MATCH($A5,Treatment_Entry!$A$5:$A$104,0)),"")) | M5: =IF($A5="","",IF(AND($E5="Not done",OR($C5="High",$C5="Very High / Locally Advanced",LEFT($C5,2)="M1")),1,0)) | N5: =IF($A5="","",IF(AND($F5="Not done",OR($C5="High",$C5="Very High / Locally Advanced")),1,0)) | O5: =IF($A5="","",IF($G5="Not started",1,0)) | P5: =IF($A5="","",IF($H5="Not done",1,0)) | Q5: =IF($A5="","",IF($I5="Not done",1,0)) | R5: =IF($A5="","",IF(AND($D5="Hormone-sensitive (HSPC)",$C5="High",$J5="Not initiated"),1,0)) | S5: =IF($A5="","",IF($K5="",1,0)) | T5: =IF($A5="","",IF(OR($L5="",$L5="Not done"),1,0)) | U5: =IF($A5="","",SUM($M5:$O5)) | V5: =IF($A5="","",SUM($P5:$R5)) | W5: =IF($A5="","",SUM($S5:$T5)) | X5: =IF($A5="","",SUM($U5:$W5)) | Y5: =IF($A5="","",IF($U5>0,"Urgent",IF($V5>0,"Warning",IF($W5>0,"Info","Closed")))) | Z5: =IF($A5="","",IF($M5=1,"Complete bone scan / SPECT",IF($N5=1,"Complete PSMA PET-CT",IF($O5=1,"Start bone protection plan",IF($P5=1,"Order DEXA",IF($Q5=1,"Order genomics",IF($R5=1,"Review ARSI intensification",IF($S5=1,"Schedule follow-up PSA",IF($T5=1,"Document psychosocial screening","No open gap"))))))))) | AA5: =IF($A5="","",IF($X5=0,"No open care gaps",$Y5&" priority · "&$Z5))
A6: =IF(Demographics_Entry!$A6="","",Demographics_Entry!$A6) | B6: =IF($A6="","",IFERROR(INDEX(Demographics_Entry!$E$5:$E$104,MATCH($A6,Demographics_Entry!$A$5:$A$104,0)),"")) | C6: =IF($A6="","",IFERROR(INDEX(Clinical_Entry!$U$5:$U$104,MATCH($A6,Clinical_Entry!$A$5:$A$104,0)),"")) | D6: =IF($A6="","",IFERROR(INDEX(Clinical_Entry!$W$5:$W$104,MATCH($A6,Clinical_Entry!$A$5:$A$104,0)),"")) | E6: =IF($A6="","",IFERROR(INDEX(Clinical_Entry!$Y$5:$Y$104,MATCH($A6,Clinical_Entry!$A$5:$A$104,0)),"")) | F6: =IF($A6="","",IFERROR(INDEX(Clinical_Entry!$Z$5:$Z$104,MATCH($A6,Clinical_Entry!$A$5:$A$104,0)),"")) | G6: =IF($A6="","",IFERROR(INDEX(Treatment_Entry!$AA$5:$AA$104,MATCH($A6,Treatment_Entry!$A$5:$A$104,0)),"")) | H6: =IF($A6="","",IFERROR(INDEX(Clinical_Entry!$AB$5:$AB$104,MATCH($A6,Clinical_Entry!$A$5:$A$104,0)),"")) | I6: =IF($A6="","",IFERROR(INDEX(Clinical_Entry!$AC$5:$AC$104,MATCH($A6,Clinical_Entry!$A$5:$A$104,0)),"")) | J6: =IF($A6="","",IFERROR(INDEX(Treatment_Entry!$K$5:$K$104,MATCH($A6,Treatment_Entry!$A$5:$A$104,0)),"")) | K6: =IF($A6="","",IFERROR(INDEX(Treatment_Entry!$AC$5:$AC$104,MATCH($A6,Treatment_Entry!$A$5:$A$104,0)),"")) | L6: =IF($A6="","",IFERROR(INDEX(Treatment_Entry!$AE$5:$AE$104,MATCH($A6,Treatment_Entry!$A$5:$A$104,0)),"")) | M6: =IF($A6="","",IF(AND($E6="Not done",OR($C6="High",$C6="Very High / Locally Advanced",LEFT($C6,2)="M1")),1,0)) | N6: =IF($A6="","",IF(AND($F6="Not done",OR($C6="High",$C6="Very High / Locally Advanced")),1,0)) | O6: =IF($A6="","",IF($G6="Not started",1,0)) | P6: =IF($A6="","",IF($H6="Not done",1,0)) | Q6: =IF($A6="","",IF($I6="Not done",1,0)) | R6: =IF($A6="","",IF(AND($D6="Hormone-sensitive (HSPC)",$C6="High",$J6="Not initiated"),1,0)) | S6: =IF($A6="","",IF($K6="",1,0)) | T6: =IF($A6="","",IF(OR($L6="",$L6="Not done"),1,0)) | U6: =IF($A6="","",SUM($M6:$O6)) | V6: =IF($A6="","",SUM($P6:$R6)) | W6: =IF($A6="","",SUM($S6:$T6)) | X6: =IF($A6="","",SUM($U6:$W6)) | Y6: =IF($A6="","",IF($U6>0,"Urgent",IF($V6>0,"Warning",IF($W6>0,"Info","Closed")))) | Z6: =IF($A6="","",IF($M6=1,"Complete bone scan / SPECT",IF($N6=1,"Complete PSMA PET-CT",IF($O6=1,"Start bone protection plan",IF($P6=1,"Order DEXA",IF($Q6=1,"Order genomics",IF($R6=1,"Review ARSI intensification",IF($S6=1,"Schedule follow-up PSA",IF($T6=1,"Document psychosocial screening","No open gap"))))))))) | AA6: =IF($A6="","",IF($X6=0,"No open care gaps",$Y6&" priority · "&$Z6))
